# 에러처리 try catch 구문

divde와 같이 안에 0이 들어가서 에러나는거(아예 앱이 퍼져버림) try catch구문으로 핸들링할 수 있음
```tsx
  const priceImpact = useMemo(() => {
    try {
      const beforeSpotPriceInOverOut = calcSpotPrice(tokenAmountIn, tokenWeightIn, tokenAmountOut, tokenWeightOut, swapFeeRate);

      const effective = divide(currentInputBaseAmount, currentOutputBaseAmount);
      return minus(divide(effective, beforeSpotPriceInOverOut), '1');
    } catch {
      return '0';
    }
  }, [tokenAmountIn, tokenWeightIn, tokenAmountOut, tokenWeightOut, swapFeeRate, currentInputBaseAmount, currentOutputBaseAmount]);
  ```