# 에러처리 try catch 구문

divde와 같이 안에 0이 들어가서 에러나는거(아예 앱이 퍼져버림) try catch구문으로 핸들링할 수 있음
```tsx
  const priceImpact = useMemo(() => {
    try {
      const beforeSpotPriceInOverOut = calcSpotPrice(tokenAmountIn, tokenWeightIn, tokenAmountOut, tokenWeightOut, swapFeeRate);

      const effective = divide(currentInputBaseAmount, currentOutputBaseAmount);
      return minus(divide(effective, beforeSpotPriceInOverOut), '1');
    } catch {
      return '0';
    }
  }, [tokenAmountIn, tokenWeightIn, tokenAmountOut, tokenWeightOut, swapFeeRate, currentInputBaseAmount, currentOutputBaseAmount]);
  ```

# error boundary와 suspense

```tsx
<NativeChainCardContainer>
// 에러가 나면
  <ErrorBoundary
    FallbackComponent={(props) => <NativeChainCardError chain={chain} isCustom={isCustom} {...props} />}
  >
  // 데이터를 가져오는 중일때
    <Suspense fallback={<NativeChainCardSkeleton chain={chain} isCustom={isCustom} />}>
      <NativeChainCard chain={chain} isCustom={isCustom} />
    </Suspense>
  </ErrorBoundary>
</NativeChainCardContainer>
```